<?xml version="1.0" ?>
<!-- =================================================================================== -->
<!-- |    This document was autogenerated by xacro from dynamixel_arm.urdf.xacro       | -->
<!-- |    EDITING THIS FILE BY HAND IS NOT RECOMMENDED                                 | -->
<!-- =================================================================================== -->
<robot name="dynamixel_arm" xmlns:xacro="http://ros.org/wiki/xacro">
  <!-- constants for robot dimentions -->
  <!-- inertial for box -->
  <!-- inertial for cylinder -->
  <!-- import Rviz color -->
  <material name="white">
    <color rgba="1 1 1 1"/>
  </material>
  <material name="gray">
    <color rgba="0.4 0.4 0.4 1"/>
  </material>
  <material name="lightgray">
    <color rgba="0.45 0.45 0.45 1"/>
  </material>
  <material name="ivory">
    <color rgba="0.54 0.53 0.56 1"/>
  </material>
  <material name="darkgray">
    <color rgba="0.35 0.35 0.35 1"/>
  </material>
  <material name="black">
    <color rgba="0.2 0.2 0.2 1"/>
  </material>
  <material name="laser_black">
    <color rgba="0.1 0.1 0.1 0.0.6"/>
  </material>
  <material name="blue">
    <color rgba="0 0 0.8 1"/>
  </material>
  <material name="red">
    <color rgba="0.8 0 0 1"/>
  </material>
  <material name="green">
    <color rgba="0 0.8 0 1"/>
  </material>
  <material name="yellow">
    <color rgba="0.8 0.8 0 1"/>
  </material>
  <material name="cyan">
    <color rgba="0 0.8 0.8 0.8"/>
  </material>
  <material name="purple">
    <color rgba="0.8 0 0.8 1"/>
  </material>
  <!-- import Gazebo -->
  <gazebo>
    <plugin filename="libgazebo_ros_control.so" name="ros_contorl">
      <robotNamespace>/dynamixel_arm</robotNamespace>
    </plugin>
  </gazebo>
  <gazebo reference="arm_base_link">
    <material>Gazebo/Orange</material>
  </gazebo>
  <gazebo reference="link1">
    <material>Gazebo/Black</material>
  </gazebo>
  <gazebo reference="link2">
    <material>Gazebo/Orange</material>
  </gazebo>
  <gazebo reference="link3">
    <material>Gazebo/Black</material>
  </gazebo>
  <gazebo reference="link4">
    <material>Gazebo/Orange</material>
  </gazebo>
  <gazebo reference="link5">
    <material>Gazebo/Black</material>
  </gazebo>
  <gazebo reference="link6">
    <material>Gazebo/Orange</material>
  </gazebo>
  <gazebo reference="link7">
    <material>Gazebo/Black</material>
  </gazebo>
  <link name="world"/>
  <joint name="fixed" type="fixed">
    <parent link="world"/>
    <child link="arm_base_link"/>
    <origin xyz="0 0 1"/>
  </joint>
  <!-- Dynamixel Arm -->
  <!--joint name="arm_base_joint" type="fixed">
		<parent link="world"/>
		<child link="arm_base_link"/>
		<origin xyz="${0.720/2-0.040+0.10} 0 ${0.360/2}" rpy="${pi} 0 0"/>
	</joint-->
  <link name="arm_base_link">
    <visual>
      <geometry>
        <mesh filename="package://infant_description/meshes/Untitled.dae"/>
      </geometry>
      <origin rpy="0 0 0" xyz="0 0 0"/>
      <material name="gray"/>
    </visual>
    <collision>
      <geometry>
        <!-- <box size="0.100 0.100 0.064"/> -->
        <mesh filename="package://infant_description/meshes/Untitled.dae"/>
      </geometry>
      <!-- <origin xyz="0 0 ${0.064/2}" rpy="0 0 0"/> -->
      <origin rpy="0 0 0" xyz="0 0 0"/>
    </collision>
    <inertial>
      <origin rpy="0 0 0" xyz="0.0075 0.0000 0.0327"/>
      <mass value="0.346"/>
      <inertia ixx="0.000324" ixy="0.0" ixz="0.0" iyy="0.000383" iyz="0.0" izz="0.000381"/>
    </inertial>
  </link>
  <joint name="joint1" type="revolute">
    <parent link="arm_base_link"/>
    <child link="link1"/>
    <origin rpy="0 0 0" xyz="0 0 0.064"/>
    <axis xyz="0 0 1"/>
    <limit effort="6.0" lower="-3.05432555556" upper="3.05432555556" velocity="5.75958533333"/>
  </joint>
  <link name="link1">
    <visual>
      <geometry>
        <mesh filename="package://infant_description/meshes/Untitled4.dae"/>
      </geometry>
      <origin rpy="1.570796 0 0" xyz="0 0 0"/>
      <material name="gray"/>
    </visual>
    <collision>
      <geometry>
        <!-- <box size="0.035 0.070 0.063"/> -->
        <mesh filename="package://infant_description/meshes/Untitled4.dae"/>
      </geometry>
      <!-- <origin xyz="0 0 ${0.063/2}" rpy="0 0 0"/> -->
      <origin rpy="1.570796 0 0" xyz="0 0 0"/>
    </collision>
    <inertial>
      <origin rpy="1.570796 0 0" xyz="0.0002 0.0367 0.0000"/>
      <mass value="0.506"/>
      <inertia ixx="0.000733" ixy="0.0" ixz="0.0" iyy="0.000495" iyz="0.0" izz="0.000424"/>
    </inertial>
  </link>
  <joint name="joint2" type="revolute">
    <parent link="link1"/>
    <child link="link2"/>
    <origin rpy="0 0 0" xyz="0 0 0.063"/>
    <axis xyz="0 -1 0"/>
    <limit effort="12.0" lower="-1.65806244444" upper="1.65806244444" velocity="5.75958533333"/>
  </joint>
  <link name="link2">
    <visual>
      <geometry>
        <mesh filename="package://infant_description/meshes/Untitled5.dae"/>
      </geometry>
      <origin rpy="0 0 0" xyz="0 0 0"/>
      <material name="gray"/>
    </visual>
    <collision>
      <geometry>
        <!-- <box size="0.035 0.035 0.250"/> -->
        <mesh filename="package://infant_description/meshes/Untitled5.dae"/>
      </geometry>
      <!-- <origin xyz="0 0 ${0.250/2}" rpy="0 0 0"/> -->
      <origin rpy="0 0 0" xyz="0 0 0"/>
    </collision>
    <inertial>
      <origin rpy="0 0 0" xyz="-0.0083 0.0001 0.1509"/>
      <mass value="0.452"/>
      <inertia ixx="0.003839" ixy="0.0" ixz="0.000159" iyy="0.000378" iyz="0.0" izz="0.000282"/>
    </inertial>
  </link>
  <joint name="joint3" type="revolute">
    <parent link="link2"/>
    <child link="link3"/>
    <origin rpy="0 0 0" xyz="0 0 0.250"/>
    <axis xyz="0 -1 0"/>
    <limit effort="6.0" lower="-2.61799333333" upper="0.174532888889" velocity="5.75958533333"/>
  </joint>
  <link name="link3">
    <visual>
      <geometry>
        <mesh filename="package://infant_description/meshes/Untitled8.dae"/>
      </geometry>
      <origin rpy="0 0 0" xyz="0 0 0"/>
      <material name="gray"/>
    </visual>
    <collision>
      <geometry>
        <!-- <box size="0.035 0.035 0.100"/> -->
        <mesh filename="package://infant_description/meshes/Untitled8.dae"/>
      </geometry>
      <!-- <origin xyz="0 0 ${0.100/2}" rpy="0 0 0"/> -->
      <origin rpy="0 0 0" xyz="0 0 0"/>
    </collision>
    <inertial>
      <origin rpy="0 0 0" xyz="-0.0193 0.0003 0.0574"/>
      <mass value="0.232"/>
      <inertia ixx="0.000230" ixy="0.0" ixz="0.0" iyy="0.000231" iyz="0.0" izz="0.000120"/>
    </inertial>
  </link>
  <joint name="joint4" type="revolute">
    <parent link="link3"/>
    <child link="link4"/>
    <origin rpy="0 0 0" xyz="0 0 0.100"/>
    <axis xyz="0 0 1"/>
    <limit effort="6.0" lower="-3.05432555556" upper="3.05432555556" velocity="5.75958533333"/>
  </joint>
  <link name="link4">
    <visual>
      <geometry>
        <mesh filename="package://infant_description/meshes/Untitled6.dae"/>
      </geometry>
      <origin rpy="1.570796 0 0" xyz="0 0 0"/>
      <material name="gray"/>
    </visual>
    <collision>
      <geometry>
        <!-- <box size="0.035 0.035 0.100"/> -->
        <mesh filename="package://infant_description/meshes/Untitled6.dae"/>
      </geometry>
      <!-- <origin xyz="0 0 ${0.100/2}" rpy="0 0 0"/> -->
      <origin rpy="1.570796 0 0" xyz="0 0 0"/>
    </collision>
    <inertial>
      <origin rpy="1.570796 0 0" xyz="0.0000 0.0589 0.0000"/>
      <mass value="0.211"/>
      <inertia ixx="0.000307" ixy="0.0" ixz="0.0" iyy="0.000061" iyz="0.0" izz="0.000299"/>
    </inertial>
  </link>
  <joint name="joint5" type="revolute">
    <parent link="link4"/>
    <child link="link5"/>
    <origin rpy="0 0 0" xyz="0 0 0.100"/>
    <axis xyz="0 -1 0"/>
    <limit effort="6.0" lower="-1.65806244444" upper="1.65806244444" velocity="5.75958533333"/>
  </joint>
  <link name="link5">
    <visual>
      <origin rpy="0 0 0" xyz="0 0 0"/>
      <geometry>
        <mesh filename="package://infant_description/meshes/Untitled7.dae"/>
      </geometry>
      <material name="gray"/>
    </visual>
    <collision>
      <!-- <origin xyz="0 0 ${0.046/2}" rpy="0 0 0" /> -->
      <origin rpy="0 0 0" xyz="0 0 0"/>
      <geometry>
        <!-- <box size="0.024 0.0475 0.046" /> -->
        <mesh filename="package://infant_description/meshes/Untitled7.dae"/>
      </geometry>
    </collision>
    <inertial>
      <origin rpy="0 0 0" xyz="-0.0013 -0.0012 0.0372"/>
      <mass value="0.118"/>
      <inertia ixx="0.000063" ixy="0.0" ixz="0.0" iyy="0.000050" iyz="0.0" izz="0.000045"/>
    </inertial>
  </link>
  <link name="gripper_link">
    <!-- <visual> -->
    <!-- <origin xyz="0 0 0" rpy="0 0 0" /> -->
    <!-- <geometry> -->
    <!-- <sphere radius="0.01"/> -->
    <!-- </geometry> -->
    <!-- <material name="gray"/> -->
    <!-- </visual> -->
    <!-- <collision> -->
    <!-- <origin xyz="0 0 0" rpy="0 0 0" /> -->
    <!-- <geometry> -->
    <!-- <sphere radius="0.01"/> -->
    <!-- </geometry> -->
    <!-- </collision> -->
    <inertial>
      <origin rpy="0 0 0" xyz="0 0 0"/>
      <mass value="0.0001"/>
      <inertia ixx="1.0" ixy="0.0" ixz="0.0" iyy="1.0" iyz="0.0" izz="1.0"/>
    </inertial>
  </link>
  <joint name="joint_gripper" type="revolute">
    <parent link="link5"/>
    <child link="gripper_link"/>
    <origin rpy="0 0 0" xyz="0 0 0.130"/>
    <limit effort="6.0" lower="-3.141592" upper="3.141592" velocity="5.75958533333"/>
    <axis xyz="1 0 0"/>
  </joint>
  <joint name="joint6" type="revolute">
    <parent link="link5"/>
    <child link="link6"/>
    <origin rpy="0 0 0" xyz="0 -0.0133 0.046"/>
    <axis xyz="-1 0 0"/>
    <limit effort="6.0" lower="-0.698131555556" upper="0.349065777778" velocity="5.75958533333"/>
  </joint>
  <link name="link6">
    <visual>
      <origin rpy="0 0 -1.570796" xyz="0 0 0"/>
      <geometry>
        <mesh filename="package://infant_description/meshes/Untitled2.dae"/>
      </geometry>
      <material name="gray"/>
    </visual>
    <collision>
      <origin rpy="0 0 -1.570796" xyz="0 0 0"/>
      <!-- <origin xyz="0 0 0" rpy="0 0 ${pi/2}" /> -->
      <geometry>
        <mesh filename="package://infant_description/meshes/Untitled2.dae"/>
        <!-- <cylinder radius="0.012" length="0.0475" /> -->
      </geometry>
    </collision>
    <inertial>
      <origin rpy="0 0 0" xyz="0.0106 -0.0020 0.0249"/>
      <mass value="0.031"/>
      <inertia ixx="0.000033" ixy="0.0" ixz="0.0" iyy="0.000027" iyz="0.0" izz="0.000012"/>
    </inertial>
  </link>
  <joint name="joint7" type="revolute">
    <parent link="link5"/>
    <child link="link7"/>
    <origin rpy="0 0 0" xyz="0 0.0133 0.046"/>
    <axis xyz="-1 0 0"/>
    <limit effort="6.0" lower="-0.698131555556" upper="0.349065777778" velocity="5.75958533333"/>
  </joint>
  <link name="link7">
    <visual>
      <origin rpy="0 0 -1.570796" xyz="0 0 0"/>
      <geometry>
        <mesh filename="package://infant_description/meshes/Untitled3.dae"/>
      </geometry>
      <material name="gray"/>
    </visual>
    <collision>
      <origin rpy="0 0 -1.570796" xyz="0 0 0"/>
      <!-- <origin xyz="0 0 0" rpy="0 0 -${pi/2}" /> -->
      <geometry>
        <!-- <cylinder radius="0.012" length="0.0475" /> -->
        <mesh filename="package://infant_description/meshes/Untitled3.dae"/>
      </geometry>
    </collision>
    <inertial>
      <origin rpy="0 0 0" xyz="-0.0119 -0.0036 0.0283"/>
      <mass value="0.027"/>
      <inertia ixx="0.000029" ixy="0.0" ixz="0.0" iyy="0.000024" iyz="0.0" izz="0.000010"/>
    </inertial>
  </link>
  <!-- transmission for Dynamixel Arm-->
  <transmission name="tran1">
    <type>transmission_interface/SimpleTransmission</type>
    <joint name="joint1">
      <hardwareInterface>PositionJointInterface</hardwareInterface>
    </joint>
    <actuator name="motor1">
      <hardwareInterface>PositionJointInterface</hardwareInterface>
      <mechanicalReduction>1</mechanicalReduction>
    </actuator>
  </transmission>
  <transmission name="tran2">
    <type>transmission_interface/SimpleTransmission</type>
    <joint name="joint2">
      <hardwareInterface>PositionJointInterface</hardwareInterface>
    </joint>
    <actuator name="motor2">
      <hardwareInterface>PositionJointInterface</hardwareInterface>
      <mechanicalReduction>1</mechanicalReduction>
    </actuator>
  </transmission>
  <transmission name="tran3">
    <type>transmission_interface/SimpleTransmission</type>
    <joint name="joint3">
      <hardwareInterface>PositionJointInterface</hardwareInterface>
    </joint>
    <actuator name="motor3">
      <hardwareInterface>PositionJointInterface</hardwareInterface>
      <mechanicalReduction>1</mechanicalReduction>
    </actuator>
  </transmission>
  <transmission name="tran4">
    <type>transmission_interface/SimpleTransmission</type>
    <joint name="joint4">
      <hardwareInterface>PositionJointInterface</hardwareInterface>
    </joint>
    <actuator name="motor4">
      <hardwareInterface>PositionJointInterface</hardwareInterface>
      <mechanicalReduction>1</mechanicalReduction>
    </actuator>
  </transmission>
  <transmission name="tran5">
    <type>transmission_interface/SimpleTransmission</type>
    <joint name="joint5">
      <hardwareInterface>PositionJointInterface</hardwareInterface>
    </joint>
    <actuator name="motor5">
      <hardwareInterface>PositionJointInterface</hardwareInterface>
      <mechanicalReduction>1</mechanicalReduction>
    </actuator>
  </transmission>
  <transmission name="tran6">
    <type>transmission_interface/SimpleTransmission</type>
    <joint name="joint6">
      <hardwareInterface>PositionJointInterface</hardwareInterface>
    </joint>
    <actuator name="motor6">
      <hardwareInterface>PositionJointInterface</hardwareInterface>
      <mechanicalReduction>1</mechanicalReduction>
    </actuator>
  </transmission>
  <transmission name="tran7">
    <type>transmission_interface/SimpleTransmission</type>
    <joint name="joint7">
      <hardwareInterface>PositionJointInterface</hardwareInterface>
    </joint>
    <actuator name="motor7">
      <hardwareInterface>PositionJointInterface</hardwareInterface>
      <mechanicalReduction>1</mechanicalReduction>
    </actuator>
  </transmission>
  <transmission name="tran_gripper">
    <type>transmission_interface/SimpleTransmission</type>
    <joint name="joint_gripper">
      <hardwareInterface>PositionJointInterface</hardwareInterface>
    </joint>
    <actuator name="motor_gripper">
      <hardwareInterface>PositionJointInterface</hardwareInterface>
      <mechanicalReduction>1</mechanicalReduction>
    </actuator>
  </transmission>
</robot>

